Workbook

Sheet SiO2_Thickness Table
Y3: Center | Z3: Near center | AA3: Near edge | AB3: Extreme Edge
C4: 융합연구단 + TES Oxide BKM split test
C5: No | D5: Run#1 | E5: Run#2 | F5: Run#3 | G5: Run#4 | H5: Run#5 | I5: Run#6 | J5: Run#7 | K5: Run#8 | L5: Run#9 | M5: Run#10 | N5: Run#11 | O5: Run#12 | P5: Run#13 | Q5: Run#14 | R5: Run#15 | S5: Run#16 | T5: Run#17 | U5: Run#18 | V5: Prerun1
C6: 1 | D6: 3339.5 | E6: 3400.28 | F6: 3223.42 | G6: 3427.89 | H6: 3577.08 | I6: 3438.52 | J6: 3673.92 | K6: 3774.64 | L6: 3275.3 | M6: 3443.34 | N6: 3591.14 | O6: 3446.07 | P6: 3448.95 | Q6: 3468.19 | R6: 3517.79 | S6: 3458.64 | T6: 3393.01 | U6: 3488.23 | V6: 3318.64
C7: 2 | D7: 3292.08 | E7: 3348.53 | F7: 3197.25 | G7: 3380.95 | H7: 3533.79 | I7: 3388.82 | J7: 3633.79 | K7: 3781.4 | L7: 3232.81 | M7: 3398.85 | N7: 3538.14 | O7: 3412.99 | P7: 3404.22 | Q7: 3422.26 | R7: 3471.92 | S7: 3413.63 | T7: 3345.5 | U7: 3442.3 | V7: 3268.7
C8: 3 | D8: 3289.93 | E8: 3357.43 | F8: 3176.61 | G8: 3392.26 | H8: 3542.13 | I8: 3397.87 | J8: 3638.76 | K8: 3739.57 | L8: 3240.03 | M8: 3409.19 | N8: 3550.94 | O8: 3400.21 | P8: 3413.89 | Q8: 3426.09 | R8: 3475.99 | S8: 3421.11 | T8: 3352.82 | U8: 3455.19 | V8: 3272.55 | X8: 49-Point Measurement
C9: 4 | D9: 3314.24 | E9: 3381.13 | F9: 3166.2 | G9: 3414.62 | H9: 3563.74 | I9: 3423.83 | J9: 3661.25 | K9: 3702.27 | L9: 3261.33 | M9: 3432.11 | N9: 3576.62 | O9: 3392.88 | P9: 3435.52 | Q9: 3451.08 | R9: 3497.77 | S9: 3445.22 | T9: 3375.41 | U9: 3476.98 | V9: 3298.32
C10: 5 | D10: 3354.01 | E10: 3418.21 | F10: 3197.45 | G10: 3446.44 | H10: 3595.24 | I10: 3457.15 | J10: 3689.66 | K10: 3727.68 | L10: 3292.05 | M10: 3462.17 | N10: 3609.76 | O10: 3426 | P10: 3467.42 | Q10: 3487.29 | R10: 3532.92 | S10: 3477.17 | T10: 3410.19 | U10: 3508.46 | V10: 3335.96
C11: 6 | D11: 3381.64 | E11: 3444.96 | F11: 3250.92 | G11: 3468.6 | H11: 3617.18 | I11: 3483.5 | J11: 3709.87 | K11: 3785.99 | L11: 3316.48 | M11: 3486.74 | N11: 3635.69 | O11: 3476.83 | P11: 3489.56 | Q11: 3511.34 | R11: 3560.61 | S11: 3502.42 | T11: 3437.8 | U11: 3529.46 | V11: 3361.87
C12: 7 | D12: 3376.34 | E12: 3437.96 | F12: 3269.56 | G12: 3462 | H12: 3610.46 | I12: 3475.37 | J12: 3706.05 | K12: 3817.22 | L12: 3308.94 | M12: 3477.35 | N12: 3628.74 | O12: 3489.03 | P12: 3481.78 | Q12: 3505.53 | R12: 3553.26 | S12: 3493.56 | T12: 3427.96 | U12: 3520.22 | V12: 3356.42
C13: 8 | D13: 3357.05 | E13: 3416.46 | F13: 3261.89 | G13: 3440.84 | H13: 3590.7 | I13: 3454.65 | J13: 3690.8 | K13: 3826.69 | L13: 3290.97 | M13: 3456.77 | N13: 3604.05 | O13: 3478.53 | P13: 3460.93 | Q13: 3482.56 | R13: 3533.26 | S13: 3470.93 | T13: 3406.65 | U13: 3498.47 | V13: 3336.56
C14: 9 | D14: 3320.23 | E14: 3377.16 | F14: 3228.73 | G14: 3405.25 | H14: 3556.2 | I14: 3416.55 | J14: 3659.61 | K14: 3811.05 | L14: 3258.03 | M14: 3422.65 | N14: 3564.37 | O14: 3442.39 | P14: 3425.49 | Q14: 3445.71 | R14: 3497.47 | S14: 3435.75 | T14: 3369.37 | U14: 3462.88 | V14: 3299.74
C15: 10 | D15: 3234.06 | E15: 3286.88 | F15: 3157.73 | G15: 3317.96 | H15: 3472.73 | I15: 3327.93 | J15: 3575.11 | K15: 3780.04 | L15: 3175.04 | M15: 3338.34 | N15: 3469.38 | O15: 3373.25 | P15: 3340.52 | Q15: 3370.52 | R15: 3412.54 | S15: 3349.6 | T15: 3282.71 | U15: 3375.55 | V15: 3210.07
C16: 11 | D16: 3214.59 | E16: 3270.77 | F16: 3130.33 | G16: 3308.03 | H16: 3460.58 | I16: 3310.89 | J16: 3557.91 | K16: 3733.49 | L16: 3161.73 | M16: 3326.09 | N16: 3457.96 | O16: 3345.83 | P16: 3330.83 | Q16: 3356.17 | R16: 3392.89 | S16: 3340.11 | T16: 3268.31 | U16: 3366.63 | V16: 3190.99
C17: 12 | D17: 3218.69 | E17: 3277.64 | F17: 3106.53 | G17: 3320.57 | H17: 3471.61 | I17: 3319.84 | J17: 3569.59 | K17: 3678.44 | L17: 3172.25 | M17: 3338.77 | N17: 3465.78 | O17: 3323.52 | P17: 3342.8 | Q17: 3362.81 | R17: 3397.45 | S17: 3349.07 | T17: 3275.38 | U17: 3378.93 | V17: 3197
C18: 13 | D18: 3245.09 | E18: 3308.27 | F18: 3085.64 | G18: 3352.09 | H18: 3503.58 | I18: 3353.14 | J18: 3605.55 | K18: 3624.84 | L18: 3201.19 | M18: 3368.7 | N18: 3499.38 | O18: 3309.83 | P18: 3373.5 | Q18: 3389.92 | R18: 3422.64 | S18: 3379.32 | T18: 3303.47 | U18: 3411.26 | V18: 3227.29
C19: 14 | D19: 3292.32 | E19: 3359.75 | F19: 3090.94 | G19: 3395.98 | H19: 3546.02 | I19: 3401.66 | J19: 3649.28 | K19: 3609.85 | L19: 3246.48 | M19: 3414.65 | N19: 3550.07 | O19: 3322.03 | P19: 3417.44 | Q19: 3436.07 | R19: 3469.16 | S19: 3424.74 | T19: 3350.66 | U19: 3455.11 | V19: 3275.16
C20: 15 | D20: 3340.47 | E20: 3404.63 | F20: 3121.71 | G20: 3438.13 | H20: 3589.28 | I20: 3447.29 | J20: 3688.94 | K20: 3631.11 | L20: 3283.3 | M20: 3455.65 | N20: 3598.55 | O20: 3360.55 | P20: 3458.7 | Q20: 3479.71 | R20: 3516.76 | S20: 3466.42 | T20: 3395.97 | U20: 3497.23 | V20: 3321.6
... C41: 36 | D41: 3330.18 | E41: 3361.15 | F41: 3112.57 | G41: 3401.69 | H41: 3539.59 | I41: 3405.5 | J41: 3629.38 | K41: 3620.73 | L41: 3255.54 | M41: 3407.26 | N41: 3542.89 | O41: 3340.23 | P41: 3413.57 | Q41: 3446.71 | R41: 3479.88 | S41: 3421.75 | T41: 3359.09 | U41: 3424.73 | V41: 3302.89
C42: 37 | D42: 3348.77 | E42: 3381.53 | F42: 3166.15 | G42: 3407.31 | H42: 3557.99 | I42: 3424.6 | J42: 3644.41 | K42: 3675.83 | L42: 3272.02 | M42: 3425.71 | N42: 3563.54 | O42: 3390.07 | P42: 3432.55 | Q42: 3463.18 | R42: 3500.47 | S42: 3442.33 | T42: 3383.45 | U42: 3442.61 | V42: 3322.07 | X42: Recipe
C43: 38 | D43: 3362.44 | E43: 3393.41 | F43: 3201.54 | G43: 3419.36 | H43: 3569.44 | I43: 3437.04 | J43: 3652.91 | K43: 3714.28 | L43: 3283.09 | M43: 3438.81 | N43: 3577.6 | O43: 3419.99 | P43: 3444.14 | Q43: 3475.8 | R43: 3512.09 | S43: 3455.03 | T43: 3395.5 | U43: 3453.4 | V43: 3333.56
C44: 39 | D44: 3371.84 | E44: 3405.6 | F44: 3230.07 | G44: 3429.51 | H44: 3581.11 | I44: 3447.86 | J44: 3663.5 | K44: 3749.3 | L44: 3293.75 | M44: 3449.2 | N44: 3588.85 | O44: 3447.61 | P44: 3455.27 | Q44: 3484.92 | R44: 3524.72 | S44: 3467.74 | T44: 3408.72 | U44: 3463.45 | V44: 3345.34
C45: 40 | D45: 3356.73 | E45: 3389.98 | F45: 3226.67 | G45: 3410.85 | H45: 3563.62 | I45: 3428 | J45: 3653.05 | K45: 3754.64 | L45: 3276.93 | M45: 3428.91 | N45: 3573.15 | O45: 3441.15 | P45: 3435.81 | Q45: 3465.44 | R45: 3507.75 | S45: 3450.4 | T45: 3392.56 | U45: 3445.39 | V45: 3329.53
C46: 41 | D46: 3346.88 | E46: 3379.93 | F46: 3223.46 | G46: 3398.46 | H46: 3553.62 | I46: 3416.29 | J46: 3647.65 | K46: 3765.46 | L46: 3266.96 | M46: 3416.12 | N46: 3558.91 | O46: 3437.85 | P46: 3425.69 | Q46: 3453.64 | R46: 3497.42 | S46: 3437.64 | T46: 3382.42 | U46: 3433.12 | V46: 3318.95
C47: 42 | D47: 3337.32 | E47: 3368.51 | F47: 3216.54 | G47: 3388.21 | H47: 3544.03 | I47: 3404.78 | J47: 3639.71 | K47: 3773.31 | L47: 3259.03 | M47: 3405.41 | N47: 3543.55 | O47: 3429.86 | P47: 3414.13 | Q47: 3445.62 | R47: 3486.02 | S47: 3427.37 | T47: 3367.44 | U47: 3420.43 | V47: 3309.69
C48: 43 | D48: 3311.17 | E48: 3343.47 | F48: 3192.42 | G48: 3362.02 | H48: 3520.37 | I48: 3378 | J48: 3620.14 | K48: 3771.32 | L48: 3236.33 | M48: 3379.71 | N48: 3512.92 | O48: 3408.23 | P48: 3386.5 | Q48: 3422.24 | R48: 3459.16 | S48: 3399.68 | T48: 3338.56 | U48: 3391.2 | V48: 3285.98
C49: 44 | D49: 3284.09 | E49: 3310.66 | F49: 3168.78 | G49: 3334.22 | H49: 3491.78 | I49: 3346.81 | J49: 3598.14 | K49: 3761.6 | L49: 3211.2 | M49: 3351.52 | N49: 3480.3 | O49: 3379.8 | P49: 3357.48 | Q49: 3395.55 | R49: 3430.18 | S49: 3381.53 | T49: 3306.78 | U49: 3362.9 | V49: 3258.19
C50: 45 | D50: 3252.91 | E50: 3278.16 | F50: 3137.77 | G50: 3300.33 | H50: 3461.25 | I50: 3316.65 | J50: 3568.81 | K50: 3749.64 | L50: 3181.17 | M50: 3321.44 | N50: 3446.24 | O50: 3346.54 | P50: 3323.29 | Q50: 3364.61 | R50: 3397.01 | S50: 3343.98 | T50: 3274.31 | U50: 3330.41 | V50: 3228.3
C51: 46 | D51: 3224.03 | E51: 3243.73 | F51: 3115.35 | G51: 3268.67 | H51: 3428.51 | I51: 3280.12 | J51: 3538.99 | K51: 3733.93 | L51: 3151.87 | M51: 3290.21 | N51: 3412.89 | O51: 3316.78 | P51: 3290.22 | Q51: 3334.73 | R51: 3363.63 | S51: 3310.36 | T51: 3242.79 | U51: 3299.54 | V51: 3197.53
C52: 47 | D52: 3198.82 | E52: 3213.78 | F52: 3088.62 | G52: 3239.36 | H52: 3399.8 | I52: 3252.6 | J52: 3510.92 | K52: 3721.99 | L52: 3124.84 | M52: 3264.54 | N52: 3380.91 | O52: 3289.67 | P52: 3261.35 | Q52: 3308.35 | R52: 3337.87 | S52: 3278.33 | T52: 3215.58 | U52: 3258.27 | V52: 3169.48
C53: 48 | D53: 3170.11 | E53: 3181.63 | F53: 3059.98 | G53: 3210.65 | H53: 3372.09 | I53: 3225.16 | J53: 3473.26 | K53: 3705.65 | L53: 3095.51 | M53: 3232.91 | N53: 3351.03 | O53: 3265.51 | P53: 3230.99 | Q53: 3279.26 | R53: 3308 | S53: 3244.76 | T53: 3188.2 | U53: 3231.54 | V53: 3138.32
C54: 49 | D54: 3133.08 | E54: 3146.79 | F54: 3034.23 | G54: 3180.18 | H54: 3333.04 | I54: 3189.64 | J54: 3436.51 | K54: 3677.23 | L54: 3065.27 | M54: 3203.45 | N54: 3311.51 | O54: 3235.59 | P54: 3200.61 | Q54: 3247.53 | R54: 3274.3 | S54: 3215.11 | T54: 3158.48 | U54: 3204.33 | V54: 3104.27
C55: THK Avg | D55: =AVERAGE(D6:D54) -> 3282.6627 | E55: =AVERAGE(E6:E54) -> 3327.2769 | F55: =AVERAGE(F6:F54) -> 3145.4935 | G55: =AVERAGE(G6:G54) -> 3357.9459 | H55: =AVERAGE(H6:H54) -> 3509.9308 | I55: =AVERAGE(I6:I54) -> 3367.9643 | J55: =AVERAGE(J6:J54) -> 3607.301 | K55: =AVERAGE(K6:K54) -> 3705.5 | ... V55: =AVERAGE(V6:V54) -> 3259.0153
C56: Max | D56: =MAX(D6:D54) -> 3424.32 | E56: =MAX(E6:E54) -> 3485.76 | F56: =MAX(F6:F54) -> 3315.07 | G56: =MAX(G6:G54) -> 3510.26 | H56: =MAX(H6:H54) -> 3657.66 | I56: =MAX(I6:I54) -> 3522.8 | J56: =MAX(J6:J54) -> 3744.48 | K56: =MAX(K6:K54) -> 3867.73 | ... V56: =MAX(V6:V54) -> 3402.55
C57: Min | D57: =MIN(D6:D54) -> 3058.11 | E57: =MIN(E6:E54) -> 3085.25 | F57: =MIN(F6:F54) -> 2921.53 | G57: =MIN(G6:G54) -> 3131.65 | H57: =MIN(H6:H54) -> 3281.8 | I57: =MIN(I6:I54) -> 3133.47 | J57: =MIN(J6:J54) -> 3369.23 | K57: =MIN(K6:K54) -> 3426.14 | ... V57: =MIN(V6:V54) -> 3028.65
C58: Total Uniformity | D58: =(D56-D57)/(D56+D57) -> 0.056492704 | E58: =(E56-E57)/(E56+E57) -> 0.060951056 | F58: =(F56-F57)/(F56+F57) -> 0.06310169 | G58: =(G56-G57)/(G56+G57) -> 0.057003181 | H58: =(H56-H57)/(H56+H57) -> 0.054162716 | I58: =(I56-I57)/(I56+I57) -> 0.058490716 | J58: =(J56-J57)/(J56+J57) -> 0.052750253 | K58: =(K56-K57)/(K56+K57) -> 0.06054262 | ... V58: =(V56-V57)/(V56+V57) -> 0.05813845
B59: EE제외 | C59: THK Avg | D59: =AVERAGE(D6:D30) -> 3332.0372 | E59: =AVERAGE(E6:E30) -> 3392.3396 | F59: =AVERAGE(F6:F30) -> 3209.916 | G59: =AVERAGE(G6:G30) -> 3421.492 | H59: =AVERAGE(H6:H30) -> 3571.7232 | I59: =AVERAGE(I6:I30) -> 3431.1208 | J59: =AVERAGE(J6:J30) -> 3670.4744 | K59: =AVERAGE(K6:K30) -> 3768.8128 | ... V59: =AVERAGE(V6:V30) -> 3311.4816
C60: Max | D60: =MAX(D6:D30) -> 3424.32 | E60: =MAX(E6:E30) -> 3485.76 | F60: =MAX(F6:F30) -> 3315.07 | G60: =MAX(G6:G30) -> 3510.26 | H60: =MAX(H6:H30) -> 3657.66 | I60: =MAX(I6:I30) -> 3522.8 | J60: =MAX(J6:J30) -> 3744.48 | K60: =MAX(K6:K30) -> 3867.73 | ... V60: =MAX(V6:V30) -> 3402.55
C61: Min | D61: =MIN(D6:D30) -> 3214.59 | E61: =MIN(E6:E30) -> 3270.77 | F61: =MIN(F6:F30) -> 3085.64 | G61: =MIN(G6:G30) -> 3308.03 | H61: =MIN(H6:H30) -> 3460.58 | I61: =MIN(I6:I30) -> 3310.89 | J61: =MIN(J6:J30) -> 3557.91 | K61: =MIN(K6:K30) -> 3609.85 | ... V61: =MIN(V6:V30) -> 3190.99
C62: Uniformity without ex edge | D62: =(D60-D61)/(D60+D61) -> 0.031591029 | E62: =(E60-E61)/(E60+E61) -> 0.031819588 | F62: =(F60-F61)/(F60+F61) -> 0.035844461 | G62: =(G60-G61)/(G60+G61) -> 0.029659929 | H62: =(H60-H61)/(H60+H61) -> 0.027686619 | I62: =(I60-I61)/(I60+I61) -> 0.031009601 | J62: =(J60-J61)/(J60+J61) -> 0.02554917 | K62: =(K60-K61)/(K60+K61) -> 0.034487093 | ... V62: =(V60-V61)/(V60+V61) -> 0.032085951 | W62: =AVERAGE(D62:V62) -> 0.030480611
...

Sheet 결과 정리
B2: Recipe name | C2: Dep_recipe | J2: CLN_recipe | P2: Releflectometer (Total) | U2: Releflectometer (EE제외)
C3: Gas(sccm) | F3: Pressure (mTorr) | G3: Power (watt) | H3: Temp (℃) | I3: Time (sec) | J3: Gas(sccm) | L3: Power (watt) | M3: Time (sec) | N3: Pressure (mTorr) | P3: THK Avg. (Å) | Q3: Max. (Å) | R3: Min. (Å) | S3: Total Uniformity (%) | U3: THK Avg. (Å) | V3: Max. (Å) | W3: Min. (Å) | X3: Total Uniformity (%)
C4: SiH4 | D4: N2O | E4: N2 | J4: NF3 | K4: Ar
B5: TES_oxide_prerun_1 | C5: 200 | D5: 4000 | E5: 3000 | F5: 2250 | G5: 400 | H5: 360 | I5: 30 | J5: 2000 | K5: 3000 | L5: 3000 | M5: 120 | N5: 2500 | P5: ='SiO2_Thickness Table'!$V$55 -> 3259.0153 | Q5: ='SiO2_Thickness Table'!$V$56 -> 3402.55 | R5: ='SiO2_Thickness Table'!$V$57 -> 3028.65 | S5: ='SiO2_Thickness Table'!$V$58 -> 0.05813845 | U5: ='SiO2_Thickness Table'!$V$59 -> 3311.4816 | V5: ='SiO2_Thickness Table'!$V$60 -> 3402.55 | W5: ='SiO2_Thickness Table'!$V$61 -> 3190.99 | X5: ='SiO2_Thickness Table'!$V$62 -> 0.032085951
B6: TES_oxide_run_1 | C6: 200 | D6: 4000 | E6: 3000 | F6: 2250 | G6: 400 | H6: 360 | I6: 30 | J6: 2000 | K6: 3000 | L6: 3000 | M6: 120 | N6: 2500 | P6: ='SiO2_Thickness Table'!$D$55 -> 3282.6627 | Q6: ='SiO2_Thickness Table'!$D$56 -> 3424.32 | R6: ='SiO2_Thickness Table'!$D$57 -> 3058.11 | S6: ='SiO2_Thickness Table'!$D$58 -> 0.056492704 | U6: ='SiO2_Thickness Table'!$D$59 -> 3332.0372 | V6: ='SiO2_Thickness Table'!$D$60 -> 3424.32 | W6: ='SiO2_Thickness Table'!$D$61 -> 3214.59 | X6: ='SiO2_Thickness Table'!$D$62 -> 0.031591029
B7: TES_oxide_run_2 | C7: 200 | D7: 4000 | E7: 3000 | F7: 2250 | G7: 400 | H7: 400 | I7: 30 | J7: 2000 | K7: 3000 | L7: 3000 | M7: 120 | N7: 2500 | P7: ='SiO2_Thickness Table'!$E$55 -> 3327.2769 | Q7: ='SiO2_Thickness Table'!$E$56 -> 3485.76 | R7: ='SiO2_Thickness Table'!$E$57 -> 3085.25 | S7: ='SiO2_Thickness Table'!$E$58 -> 0.060951056 | U7: ='SiO2_Thickness Table'!$E$59 -> 3392.3396 | V7: ='SiO2_Thickness Table'!$E$60 -> 3485.76 | W7: ='SiO2_Thickness Table'!$E$61 -> 3270.77 | X7: ='SiO2_Thickness Table'!$E$62 -> 0.031819588
B8: TES_oxide_run_3 | C8: 200 | D8: 4000 | E8: 3000 | F8: 2250 | G8: 360 | H8: 400 | I8: 30 | J8: 2000 | K8: 3000 | L8: 3000 | M8: 120 | N8: 2500 | P8: ='SiO2_Thickness Table'!$F$55 -> 3145.4935 | Q8: ='SiO2_Thickness Table'!$F$56 -> 3315.07 | R8: ='SiO2_Thickness Table'!$F$57 -> 2921.53 | S8: ='SiO2_Thickness Table'!$F$58 -> 0.06310169 | U8: ='SiO2_Thickness Table'!$F$59 -> 3209.916 | V8: ='SiO2_Thickness Table'!$F$60 -> 3315.07 | W8: ='SiO2_Thickness Table'!$F$61 -> 3085.64 | X8: ='SiO2_Thickness Table'!$F$62 -> 0.035844461
B9: TES_oxide_run_4 | C9: 200 | D9: 4000 | E9: 3000 | F9: 2250 | G9: 400 | H9: 400 | I9: 30 | J9: 2000 | K9: 3000 | L9: 3000 | M9: 120 | N9: 2500 | P9: ='SiO2_Thickness Table'!$G$55 -> 3357.9459 | Q9: ='SiO2_Thickness Table'!$G$56 -> 3510.26 | R9: ='SiO2_Thickness Table'!$G$57 -> 3131.65 | S9: ='SiO2_Thickness Table'!$G$58 -> 0.057003181 | U9: ='SiO2_Thickness Table'!$G$59 -> 3421.492 | V9: ='SiO2_Thickness Table'!$G$60 -> 3510.26 | W9: ='SiO2_Thickness Table'!$G$61 -> 3308.03 | X9: ='SiO2_Thickness Table'!$G$62 -> 0.029659929
B10: TES_oxide_run_5 | C10: 200 | D10: 4000 | E10: 3000 | F10: 2250 | G10: 440 | H10: 400 | I10: 30 | J10: 2000 | K10: 3000 | L10: 3000 | M10: 120 | N10: 2500 | P10: ='SiO2_Thickness Table'!$H$55 -> 3509.9308 | Q10: ='SiO2_Thickness Table'!$H$56 -> 3657.66 | R10: ='SiO2_Thickness Table'!$H$57 -> 3281.8 | S10: ='SiO2_Thickness Table'!$H$58 -> 0.054162716 | U10: ='SiO2_Thickness Table'!$H$59 -> 3571.7232 | V10: ='SiO2_Thickness Table'!$H$60 -> 3657.66 | W10: ='SiO2_Thickness Table'!$H$61 -> 3460.58 | X10: ='SiO2_Thickness Table'!$H$62 -> 0.027686619
B11: TES_oxide_run_6 | C11: 200 | D11: 4000 | E11: 3000 | F11: 2250 | G11: 400 | H11: 400 | I11: 30 | J11: 2000 | K11: 3000 | L11: 3000 | M11: 120 | N11: 2500 | P11: ='SiO2_Thickness Table'!$I$55 -> 3367.9643 | Q11: ='SiO2_Thickness Table'!$I$56 -> 3522.8 | R11: ='SiO2_Thickness Table'!$I$57 -> 3133.47 | S11: ='SiO2_Thickness Table'!$I$58 -> 0.058490716 | U11: ='SiO2_Thickness Table'!$I$59 -> 3431.1208 | V11: ='SiO2_Thickness Table'!$I$60 -> 3522.8 | W11: ='SiO2_Thickness Table'!$I$61 -> 3310.89 | X11: ='SiO2_Thickness Table'!$I$62 -> 0.031009601
B12: TES_oxide_run_7 | C12: 200 | D12: 4000 | E12: 3000 | F12: 2500 | G12: 400 | H12: 400 | I12: 30 | J12: 2000 | K12: 3000 | L12: 3000 | M12: 120 | N12: 2500 | P12: ='SiO2_Thickness Table'!$J$55 -> 3607.301 | Q12: ='SiO2_Thickness Table'!$J$56 -> 3744.48 | R12: ='SiO2_Thickness Table'!$J$57 -> 3369.23 | S12: ='SiO2_Thickness Table'!$J$58 -> 0.052750253 | U12: ='SiO2_Thickness Table'!$J$59 -> 3670.4744 | V12: ='SiO2_Thickness Table'!$J$60 -> 3744.48 | W12: ='SiO2_Thickness Table'!$J$61 -> 3557.91 | X12: ='SiO2_Thickness Table'!$J$62 -> 0.02554917
B13: TES_oxide_run_8 | C13: 200 | D13: 4000 | E13: 3000 | F13: 2750 | G13: 400 | H13: 400 | I13: 30 | J13: 2000 | K13: 3000 | L13: 3000 | M13: 120 | N13: 2500 | P13: ='SiO2_Thickness Table'!$K$55 -> 3705.5 | Q13: ='SiO2_Thickness Table'!$K$56 -> 3867.73 | R13: ='SiO2_Thickness Table'!$K$57 -> 3426.14 | S13: ='SiO2_Thickness Table'!$K$58 -> 0.06054262 | U13: ='SiO2_Thickness Table'!$K$59 -> 3768.8128 | V13: ='SiO2_Thickness Table'!$K$60 -> 3867.73 | W13: ='SiO2_Thickness Table'!$K$61 -> 3609.85 | X13: ='SiO2_Thickness Table'!$K$62 -> 0.034487093
B14: TES_oxide_run_9 | C14: 180 | D14: 4000 | E14: 3000 | F14: 2250 | G14: 400 | H14: 400 | I14: 30 | J14: 2000 | K14: 3000 | L14: 3000 | M14: 120 | N14: 2500 | P14: ='SiO2_Thickness Table'!$L$55 -> 3219.068 | Q14: ='SiO2_Thickness Table'!$L$56 -> 3354.56 | R14: ='SiO2_Thickness Table'!$L$57 -> 3008.17 | S14: ='SiO2_Thickness Table'!$L$58 -> 0.054440468 | U14: ='SiO2_Thickness Table'!$L$59 -> 3270.7432 | V14: ='SiO2_Thickness Table'!$L$60 -> 3354.56 | W14: ='SiO2_Thickness Table'!$L$61 -> 3161.73 | X14: ='SiO2_Thickness Table'!$L$62 -> 0.029591992
B15: TES_oxide_run_10 | C15: 200 | D15: 4000 | E15: 3000 | F15: 2250 | G15: 400 | H15: 400 | I15: 30 | J15: 2000 | K15: 3000 | L15: 3000 | M15: 120 | N15: 2500 | P15: ='SiO2_Thickness Table'!$M$55 -> 3375.5533 | Q15: ='SiO2_Thickness Table'!$M$56 -> 3524.86 | R15: ='SiO2_Thickness Table'!$M$57 -> 3150.63 | S15: ='SiO2_Thickness Table'!$M$58 -> 0.056060304 | U15: ='SiO2_Thickness Table'!$M$59 -> 3437.9116 | V15: ='SiO2_Thickness Table'!$M$60 -> 3524.86 | W15: ='SiO2_Thickness Table'!$M$61 -> 3326.09 | X15: ='SiO2_Thickness Table'!$M$62 -> 0.029013494
B16: TES_oxide_run_11 | C16: 220 | D16: 4000 | E16: 3000 | F16: 2250 | G16: 400 | H16: 400 | I16: 30 | J16: 2000 | K16: 3000 | L16: 3000 | M16: 120 | N16: 2500 | P16: ='SiO2_Thickness Table'!$N$55 -> 3508.4518 | Q16: ='SiO2_Thickness Table'!$N$56 -> 3680.26 | R16: ='SiO2_Thickness Table'!$N$57 -> 3249.67 | S16: ='SiO2_Thickness Table'!$N$58 -> 0.062134827 | U16: ='SiO2_Thickness Table'!$N$59 -> 3581.2336 | V16: ='SiO2_Thickness Table'!$N$60 -> 3680.26 | W16: ='SiO2_Thickness Table'!$N$61 -> 3457.96 | X16: ='SiO2_Thickness Table'!$N$62 -> 0.031142218
B17: TES_oxide_run_12 | C17: 200 | D17: 3600 | E17: 3000 | F17: 2250 | G17: 400 | H17: 400 | I17: 30 | J17: 2000 | K17: 3000 | L17: 3000 | M17: 120 | N17: 2500 | P17: ='SiO2_Thickness Table'!$O$55 -> 3361.5837 | Q17: ='SiO2_Thickness Table'!$O$56 -> 3534.09 | R17: ='SiO2_Thickness Table'!$O$57 -> 3127.68 | S17: ='SiO2_Thickness Table'!$O$58 -> 0.061006309 | U17: ='SiO2_Thickness Table'!$O$59 -> 3431.8556 | V17: ='SiO2_Thickness Table'!$O$60 -> 3534.09 | W17: ='SiO2_Thickness Table'!$O$61 -> 3309.83 | X17: ='SiO2_Thickness Table'!$O$62 -> 0.032767771
B18: TES_oxide_run_13 | C18: 200 | D18: 4000 | E18: 3000 | F18: 2250 | G18: 400 | H18: 400 | I18: 30 | J18: 2000 | K18: 3000 | L18: 3000 | M18: 120 | N18: 2500 | P18: ='SiO2_Thickness Table'!$P$55 -> 3379.7451 | Q18: ='SiO2_Thickness Table'!$P$56 -> 3531.1 | R18: ='SiO2_Thickness Table'!$P$57 -> 3154.98 | S18: ='SiO2_Thickness Table'!$P$58 -> 0.056254188 | U18: ='SiO2_Thickness Table'!$P$59 -> 3442.0256 | V18: ='SiO2_Thickness Table'!$P$60 -> 3531.1 | W18: ='SiO2_Thickness Table'!$P$61 -> 3330.83 | X18: ='SiO2_Thickness Table'!$P$62 -> 0.029185666
B19: TES_oxide_run_14 | C19: 200 | D19: 4400 | E19: 3000 | F19: 2250 | G19: 400 | H19: 400 | I19: 30 | J19: 2000 | K19: 3000 | L19: 3000 | M19: 120 | N19: 2500 | P19: ='SiO2_Thickness Table'!$Q$55 -> 3408.1049 | Q19: ='SiO2_Thickness Table'!$Q$56 -> 3551.92 | R19: ='SiO2_Thickness Table'!$Q$57 -> 3184.77 | S19: ='SiO2_Thickness Table'!$Q$58 -> 0.054500059 | U19: ='SiO2_Thickness Table'!$Q$59 -> 3464.3412 | V19: ='SiO2_Thickness Table'!$Q$60 -> 3551.92 | W19: ='SiO2_Thickness Table'!$Q$61 -> 3356.17 | X19: ='SiO2_Thickness Table'!$Q$62 -> 0.028336342
B20: TES_oxide_run_15 | C20: 200 | D20: 4000 | E20: 2700 | F20: 2250 | G20: 400 | H20: 400 | I20: 30 | J20: 2000 | K20: 3000 | L20: 3000 | M20: 120 | N20: 2500 | P20: ='SiO2_Thickness Table'!$R$55 -> 3444.7878 | Q20: ='SiO2_Thickness Table'!$R$56 -> 3600.47 | R20: ='SiO2_Thickness Table'!$R$57 -> 3206.29 | S20: ='SiO2_Thickness Table'!$R$58 -> 0.057910078 | U20: ='SiO2_Thickness Table'!$R$59 -> 3509.2052 | V20: ='SiO2_Thickness Table'!$R$60 -> 3600.47 | W20: ='SiO2_Thickness Table'!$R$61 -> 3392.89 | X20: ='SiO2_Thickness Table'!$R$62 -> 0.029682442
B21: TES_oxide_run_16 | C21: 200 | D21: 4000 | E21: 3000 | F21: 2250 | G21: 400 | H21: 400 | I21: 30 | J21: 2000 | K21: 3000 | L21: 3000 | M21: 120 | N21: 2500 | P21: ='SiO2_Thickness Table'!$S$55 -> 3390.262 | Q21: ='SiO2_Thickness Table'!$S$56 -> 3540.89 | R21: ='SiO2_Thickness Table'!$S$57 -> 3161.41 | S21: ='SiO2_Thickness Table'!$S$58 -> 0.056619369 | U21: ='SiO2_Thickness Table'!$S$59 -> 3451.6888 | V21: ='SiO2_Thickness Table'!$S$60 -> 3540.89 | W21: ='SiO2_Thickness Table'!$S$61 -> 3340.11 | X21: ='SiO2_Thickness Table'!$S$62 -> 0.029178898
B22: TES_oxide_run_17 | C22: 200 | D22: 4000 | E22: 3300 | F22: 2250 | G22: 400 | H22: 400 | I22: 30 | J22: 2000 | K22: 3000 | L22: 3000 | M22: 120 | N22: 2500 | P22: ='SiO2_Thickness Table'!$T$55 -> 3324.3316 | Q22: ='SiO2_Thickness Table'!$T$56 -> 3477.88 | R22: ='SiO2_Thickness Table'!$T$57 -> 3094.89 | S22: ='SiO2_Thickness Table'!$T$58 -> 0.058269192 | U22: ='SiO2_Thickness Table'!$T$59 -> 3384.3452 | V22: ='SiO2_Thickness Table'!$T$60 -> 3477.88 | W22: ='SiO2_Thickness Table'!$T$61 -> 3268.31 | X22: ='SiO2_Thickness Table'!$T$62 -> 0.031064942
B23: TES_oxide_run_18 | C23: 200 | D23: 4000 | E23: 3000 | F23: 2250 | G23: 400 | H23: 440 | I23: 30 | J23: 2000 | K23: 3000 | L23: 3000 | M23: 120 | N23: 2500 | P23: ='SiO2_Thickness Table'!$U$55 -> 3401.8394 | Q23: ='SiO2_Thickness Table'!$U$56 -> 3570.83 | R23: ='SiO2_Thickness Table'!$U$57 -> 3159.13 | S23: ='SiO2_Thickness Table'!$U$58 -> 0.061174212 | U23: ='SiO2_Thickness Table'!$U$59 -> 3480.0932 | V23: ='SiO2_Thickness Table'!$U$60 -> 3570.83 | W23: ='SiO2_Thickness Table'!$U$61 -> 3366.63 | X23: ='SiO2_Thickness Table'!$U$62 -> 0.029434404

Sheet 결과 분석
B2: Best known method (BKM) recipe
B3: Dep_recipe | I3: CLN_recipe
B4: Gas(sccm) | E4: Pressure (mTorr) | F4: Power (watt) | G4: Temp | H4: Time (sec) | I4: Gas(sccm) | K4: Power (watt) | L4: Time (sec) | M4: Pressure (mTorr)
B5: SiH4 | C5: N2O | D5: N2 | I5: NF3 | J5: Ar
B6: 200 | C6: 4000 | D6: 3000 | E6: 2250 | F6: 400 | G6: 360 | H6: 30 | I6: 2000 | J6: 3000 | K6: 3000 | L6: 120 | M6: 2500
B9: 변수에 따른 계측 결과 변화 | N9: 재현성
B11: Reflectometer (Total) | F11: Reflectometer (EE제외) | N11: 온도 (360 ℃) - prerun 포함 | R11: 온도 (400 ℃)
N12: Recipe name | O12: THK Avg. (Å) | P12: Total Uniformity (%) | R12: Recipe name | S12: THK Avg. (Å) | T12: Total Uniformity (%)
B13: Power split | F13: Power split | N13: TES_oxide_prerun_1 | O13: ='SiO2_Thickness Table'!$V$55 -> 3259.0153 | P13: ='SiO2_Thickness Table'!$V$58 -> 0.05813845 | R13: TES_oxide_run_2 | S13: ='SiO2_Thickness Table'!$E$55 -> 3327.2769 | T13: ='SiO2_Thickness Table'!$E$58 -> 0.060951056
B14: Power (watt) | C14: THK Avg. (Å) | D14: Total Uniformity (%) | F14: Power (watt) | G14: THK Avg. (Å) | H14: Total Uniformity (%) | N14: TES_oxide_run_1 | O14: ='SiO2_Thickness Table'!$D$55 -> 3282.6627 | P14: ='SiO2_Thickness Table'!$D$58 -> 0.056492704 | R14: TES_oxide_run_4 | S14: ='SiO2_Thickness Table'!$G$55 -> 3357.9459 | T14: ='SiO2_Thickness Table'!$G$58 -> 0.057003181
B15: 360 | C15: ='SiO2_Thickness Table'!$F$55 -> 3145.4935 | D15: ='SiO2_Thickness Table'!$F$58 -> 0.06310169 | F15: 360 | G15: ='SiO2_Thickness Table'!$F$59 -> 3209.916 | H15: ='SiO2_Thickness Table'!$F$62 -> 0.035844461 | R15: TES_oxide_run_6 | S15: ='SiO2_Thickness Table'!$I$55 -> 3367.9643 | T15: ='SiO2_Thickness Table'!$I$58 -> 0.058490716
B16: 400 | C16: ='SiO2_Thickness Table'!$G$55 -> 3357.9459 | D16: ='SiO2_Thickness Table'!$G$58 -> 0.057003181 | F16: 400 | G16: ='SiO2_Thickness Table'!$G$59 -> 3421.492 | H16: ='SiO2_Thickness Table'!$G$62 -> 0.029659929 | R16: TES_oxide_run_10 | S16: ='SiO2_Thickness Table'!$M$55 -> 3375.5533 | T16: ='SiO2_Thickness Table'!$M$58 -> 0.056060304
B17: 440 | C17: ='SiO2_Thickness Table'!$H$55 -> 3509.9308 | D17: ='SiO2_Thickness Table'!$H$58 -> 0.054162716 | F17: 440 | G17: ='SiO2_Thickness Table'!$H$59 -> 3571.7232 | H17: ='SiO2_Thickness Table'!$H$62 -> 0.027686619 | R17: TES_oxide_run_13 | S17: ='SiO2_Thickness Table'!$P$55 -> 3379.7451 | T17: ='SiO2_Thickness Table'!$P$58 -> 0.056254188
R18: TES_oxide_run_16 | S18: ='SiO2_Thickness Table'!$S$55 -> 3390.262 | T18: ='SiO2_Thickness Table'!$S$58 -> 0.056619369
B19: Pressure split | F19: Pressure split
B20: Pressure (mTorr) | C20: THK Avg. (Å) | D20: Total Uniformity (%) | F20: Pressure (mTorr) | G20: THK Avg. (Å) | H20: Total Uniformity (%) | N20: 온도 (360 ℃) - prerun 포함 (EE 제외) | R20: 온도 (400 ℃) (EE제외)
B21: 2250 | C21: ='SiO2_Thickness Table'!$I$55 -> 3367.9643 | D21: ='SiO2_Thickness Table'!$I$58 -> 0.058490716 | F21: 2250 | G21: ='SiO2_Thickness Table'!$I$59 -> 3431.1208 | H21: ='SiO2_Thickness Table'!$I$62 -> 0.031009601 | N21: Recipe name | O21: THK Avg. (Å) | P21: Total Uniformity (%) | R21: Recipe name | S21: THK Avg. (Å) | T21: Total Uniformity (%)
B22: 2500 | C22: ='SiO2_Thickness Table'!$J$55 -> 3607.301 | D22: ='SiO2_Thickness Table'!$J$58 -> 0.052750253 | F22: 2500 | G22: ='SiO2_Thickness Table'!$J$59 -> 3670.4744 | H22: ='SiO2_Thickness Table'!$J$62 -> 0.02554917 | N22: TES_oxide_prerun_1 | O22: ='SiO2_Thickness Table'!$V$59 -> 3311.4816 | P22: ='SiO2_Thickness Table'!$V$62 -> 0.032085951 | R22: TES_oxide_run_2 | S22: ='SiO2_Thickness Table'!$E$59 -> 3392.3396 | T22: ='SiO2_Thickness Table'!$E$62 -> 0.031819588
B23: 2750 | C23: ='SiO2_Thickness Table'!$K$55 -> 3705.5 | D23: ='SiO2_Thickness Table'!$K$58 -> 0.06054262 | F23: 2750 | G23: ='SiO2_Thickness Table'!$K$59 -> 3768.8128 | H23: ='SiO2_Thickness Table'!$K$62 -> 0.034487093 | N23: TES_oxide_run_1 | O23: ='SiO2_Thickness Table'!$D$59 -> 3332.0372 | P23: ='SiO2_Thickness Table'!$D$62 -> 0.031591029 | R23: TES_oxide_run_4 | S23: ='SiO2_Thickness Table'!$G$59 -> 3421.492 | T23: ='SiO2_Thickness Table'!$G$62 -> 0.029659929
R24: TES_oxide_run_6 | S24: ='SiO2_Thickness Table'!$I$59 -> 3431.1208 | T24: ='SiO2_Thickness Table'!$I$62 -> 0.031009601
B25: Temperature split | F25: Temperature split | R25: TES_oxide_run_10 | S25: ='SiO2_Thickness Table'!$M$59 -> 3437.9116 | T25: ='SiO2_Thickness Table'!$M$62 -> 0.029013494
B26: Temperature (℃) | C26: THK Avg. (Å) | D26: Total Uniformity (%) | F26: Temperature (℃) | G26: THK Avg. (Å) | H26: Total Uniformity (%) | R26: TES_oxide_run_13 | S26: ='SiO2_Thickness Table'!$P$59 -> 3442.0256 | T26: ='SiO2_Thickness Table'!$P$62 -> 0.029185666
B27: 360 | C27: ='SiO2_Thickness Table'!$D$55 -> 3282.6627 | D27: ='SiO2_Thickness Table'!$D$58 -> 0.056492704 | F27: 360 | G27: ='SiO2_Thickness Table'!$D$59 -> 3332.0372 | H27: ='SiO2_Thickness Table'!$D$62 -> 0.031591029 | R27: TES_oxide_run_16 | S27: ='SiO2_Thickness Table'!$S$59 -> 3451.6888 | T27: ='SiO2_Thickness Table'!$S$62 -> 0.029178898
B28: 400 | C28: ='SiO2_Thickness Table'!$E$55 -> 3327.2769 | D28: ='SiO2_Thickness Table'!$E$58 -> 0.060951056 | F28: 400 | G28: ='SiO2_Thickness Table'!$E$59 -> 3392.3396 | H28: ='SiO2_Thickness Table'!$E$62 -> 0.031819588
B29: 440 | C29: ='SiO2_Thickness Table'!$U$55 -> 3401.8394 | D29: ='SiO2_Thickness Table'!$U$58 -> 0.061174212 | F29: 440 | G29: ='SiO2_Thickness Table'!$U$59 -> 3480.0932 | H29: ='SiO2_Thickness Table'!$U$62 -> 0.029434404
B31: SiH4 split | F31: SiH4 split
B32: SiH4 (sccm) | C32: THK Avg. (Å) | D32: Total Uniformity (%) | F32: SiH4 (sccm) | G32: THK Avg. (Å) | H32: Total Uniformity (%)
B33: 180 | C33: ='SiO2_Thickness Table'!$L$55 -> 3219.068 | D33: ='SiO2_Thickness Table'!$L$58 -> 0.054440468 | F33: 180 | G33: ='SiO2_Thickness Table'!$L$59 -> 3270.7432 | H33: ='SiO2_Thickness Table'!$L$62 -> 0.029591992
B34: 200 | C34: ='SiO2_Thickness Table'!$M$55 -> 3375.5533 | D34: ='SiO2_Thickness Table'!$M$58 -> 0.056060304 | F34: 200 | G34: ='SiO2_Thickness Table'!$M$59 -> 3437.9116 | H34: ='SiO2_Thickness Table'!$M$62 -> 0.029013494
B35: 220 | C35: ='SiO2_Thickness Table'!$N$55 -> 3508.4518 | D35: ='SiO2_Thickness Table'!$N$58 -> 0.062134827 | F35: 220 | G35: ='SiO2_Thickness Table'!$N$59 -> 3581.2336 | H35: ='SiO2_Thickness Table'!$N$62 -> 0.031142218
B37: N2O split | F37: N2O split
B38: N2O (sccm) | C38: THK Avg. (Å) | D38: Total Uniformity (%) | F38: N2O (sccm) | G38: THK Avg. (Å) | H38: Total Uniformity (%)
B39: 3600 | C39: ='SiO2_Thickness Table'!$O$55 -> 3361.5837 | D39: ='SiO2_Thickness Table'!$O$58 -> 0.061006309 | F39: 3600 | G39: ='SiO2_Thickness Table'!$O$59 -> 3431.8556 | H39: ='SiO2_Thickness Table'!$O$62 -> 0.032767771
B40: 4000 | C40: ='SiO2_Thickness Table'!$P$55 -> 3379.7451 | D40: ='SiO2_Thickness Table'!$P$58 -> 0.056254188 | F40: 4000 | G40: ='SiO2_Thickness Table'!$P$59 -> 3442.0256 | H40: ='SiO2_Thickness Table'!$P$62 -> 0.029185666
B41: 4400 | C41: ='SiO2_Thickness Table'!$Q$55 -> 3408.1049 | D41: ='SiO2_Thickness Table'!$Q$58 -> 0.054500059 | F41: 4400 | G41: ='SiO2_Thickness Table'!$Q$59 -> 3464.3412 | H41: ='SiO2_Thickness Table'!$Q$62 -> 0.028336342
B43: N2 split | F43: N2 split
B44: N2 (sccm) | C44: THK Avg. (Å) | D44: Total Uniformity (%) | F44: N2 (sccm) | G44: THK Avg. (Å) | H44: Total Uniformity (%)
B45: 2700 | C45: ='SiO2_Thickness Table'!$R$55 -> 3444.7878 | D45: ='SiO2_Thickness Table'!$R$58 -> 0.057910078 | F45: 2700 | G45: ='SiO2_Thickness Table'!$R$59 -> 3509.2052 | H45: ='SiO2_Thickness Table'!$R$62 -> 0.029682442
B46: 3000 | C46: ='SiO2_Thickness Table'!$S$55 -> 3390.262 | D46: ='SiO2_Thickness Table'!$S$58 -> 0.056619369 | F46: 3000 | G46: ='SiO2_Thickness Table'!$S$59 -> 3451.6888 | H46: ='SiO2_Thickness Table'!$S$62 -> 0.029178898
B47: 3300 | C47: ='SiO2_Thickness Table'!$T$55 -> 3324.3316 | D47: ='SiO2_Thickness Table'!$T$58 -> 0.058269192 | F47: 3300 | G47: ='SiO2_Thickness Table'!$T$59 -> 3384.3452 | H47: ='SiO2_Thickness Table'!$T$62 -> 0.031064942
